Workbook

Sheet Datos de Carreras
A1: Nombres | B1: Ronda 1 | C1: Ronda 2 | D1: Ronda 3 | E1: Edad | F1: Pais | I1: Etiquetas de fila | J1: Cuenta de Ronda 2 | L1: Etiquetas de fila | M1: Cuenta de Nombres
A2: WILLIAMS Christania | B2: 11.27 | C2: 10.96 | D2: 11.8 | E2: =VLOOKUP(A2,'Edades de Competidores'!$A$1:$B$65,2,0) -> 21.84 | F2: =VLOOKUP(A2,'Paises Participantes'!$A$1:$B$65,2,0) -> JAM | I2: 18-19 | L2: USA | M2: 3
A3: THOMPSON Elaine | B3: 11.21 | C3: 10.88 | D3: 10.71 | E3: =VLOOKUP(A3,'Edades de Competidores'!$A$1:$B$65,2,0) -> 24.14 | F3: =VLOOKUP(A3,'Paises Participantes'!$A$1:$B$65,2,0) -> JAM | I3: 19-20 | J3: 1 | L3: Total general | M3: 3
A4: SCHIPPERS Dafne | B4: 11.16 | C4: 10.9 | D4: 10.9 | E4: =VLOOKUP(A4,'Edades de Competidores'!$A$1:$B$65,2,0) -> 24.18 | F4: =VLOOKUP(A4,'Paises Participantes'!$A$1:$B$65,2,0) -> NED | I4: 20-21 | J4: 2
A5: GARDNER English | B5: 11.09 | C5: 10.9 | D5: 10.94 | E5: =VLOOKUP(A5,'Edades de Competidores'!$A$1:$B$65,2,0) -> 24.33 | F5: =VLOOKUP(A5,'Paises Participantes'!$A$1:$B$65,2,0) -> USA | I5: 21-22 | J5: 1
A6: AHYE Michelle-Lee | B6: 11 | C6: 10.9 | D6: 10.92 | E6: =VLOOKUP(A6,'Edades de Competidores'!$A$1:$B$65,2,0) -> 24.36 | F6: =VLOOKUP(A6,'Paises Participantes'!$A$1:$B$65,2,0) -> TTO | I6: 22-23
A7: BOWIE Tori | B7: 11.13 | C7: 10.9 | D7: 10.83 | E7: =VLOOKUP(A7,'Edades de Competidores'!$A$1:$B$65,2,0) -> 25.98 | F7: =VLOOKUP(A7,'Paises Participantes'!$A$1:$B$65,2,0) -> USA | I7: 23-24
A8: TA LOU Marie-Josee | B8: 11.01 | C8: 10.94 | D8: 10.86 | E8: =VLOOKUP(A8,'Edades de Competidores'!$A$1:$B$65,2,0) -> 27.75 | F8: =VLOOKUP(A8,'Paises Participantes'!$A$1:$B$65,2,0) -> CIV | I8: 24-25 | J8: 6
A9: FRASER-PRYCE Shelly-Ann | B9: 10.96 | C9: 10.88 | D9: 10.86 | E9: =VLOOKUP(A9,'Edades de Competidores'!$A$1:$B$65,2,0) -> 29.65 | F9: =VLOOKUP(A9,'Paises Participantes'!$A$1:$B$65,2,0) -> JAM | I9: 25-26 | J9: 4
A10: PHILIP Asha | B10: 11.34 | C10: 11.33 | E10: =VLOOKUP(A10,'Edades de Competidores'!$A$1:$B$65,2,0) -> 25.82 | F10: =VLOOKUP(A10,'Paises Participantes'!$A$1:$B$65,2,0) -> GBR | I10: 26-27
A11: POHREBNIAK Natalia | B11: 11.3 | C11: 11.32 | E11: =VLOOKUP(A11,'Edades de Competidores'!$A$1:$B$65,2,0) -> 28.5 | F11: =VLOOKUP(A11,'Paises Participantes'!$A$1:$B$65,2,0) -> UKR | I11: 27-28 | J11: 4
A12: PINTO Tatjana | B12: 11.31 | C12: 11.32 | E12: =VLOOKUP(A12,'Edades de Competidores'!$A$1:$B$65,2,0) -> 24.13 | F12: =VLOOKUP(A12,'Paises Participantes'!$A$1:$B$65,2,0) -> GER | I12: 28-29 | J12: 3
A13: POVKH Olesya | B13: 11.39 | C13: 11.29 | E13: =VLOOKUP(A13,'Edades de Competidores'!$A$1:$B$65,2,0) -> 28.84 | F13: =VLOOKUP(A13,'Paises Participantes'!$A$1:$B$65,2,0) -> UKR | I13: 29-30 | J13: 1
A14: LANDAZURI Narcisa | B14: 11.38 | C14: 11.27 | E14: =VLOOKUP(A14,'Edades de Competidores'!$A$1:$B$65,2,0) -> 25.19 | F14: =VLOOKUP(A14,'Paises Participantes'!$A$1:$B$65,2,0) -> ECU | I14: 30-31 | J14: 1
A15: SANTOS Rosangela | B15: 11.25 | C15: 11.23 | E15: =VLOOKUP(A15,'Edades de Competidores'!$A$1:$B$65,2,0) -> 25.67 | F15: =VLOOKUP(A15,'Paises Participantes'!$A$1:$B$65,2,0) -> BRA | I15: 31-32
A16: HORN Carina | B16: 11.32 | C16: 11.2 | E16: =VLOOKUP(A16,'Edades de Competidores'!$A$1:$B$65,2,0) -> 27.45 | F16: =VLOOKUP(A16,'Paises Participantes'!$A$1:$B$65,2,0) -> RSA | I16: 32-33
A17: HACKETT Semoy | B17: 11.35 | C17: 11.2 | E17: =VLOOKUP(A17,'Edades de Competidores'!$A$1:$B$65,2,0) -> 27.73 | F17: =VLOOKUP(A17,'Paises Participantes'!$A$1:$B$65,2,0) -> TTO | I17: 33-34
A18: SWOBODA Ewa | B18: 11.24 | C18: 11.18 | E18: =VLOOKUP(A18,'Edades de Competidores'!$A$1:$B$65,2,0) -> 19.06 | F18: =VLOOKUP(A18,'Paises Participantes'!$A$1:$B$65,2,0) -> POL | I18: 34-35
A19: KAMBUNDJI Mujinga | B19: 11.19 | C19: 11.16 | E19: =VLOOKUP(A19,'Edades de Competidores'!$A$1:$B$65,2,0) -> 24.17 | F19: =VLOOKUP(A19,'Paises Participantes'!$A$1:$B$65,2,0) -> SUI | I19: Total general | J19: 23
A20: TENORIO Angela | B20: 11.35 | C20: 11.14 | E20: =VLOOKUP(A20,'Edades de Competidores'!$A$1:$B$65,2,0) -> 20.56 | F20: =VLOOKUP(A20,'Paises Participantes'!$A$1:$B$65,2,0) -> ECU
A21: HENRY Desiree | B21: 11.08 | C21: 11.09 | E21: =VLOOKUP(A21,'Edades de Competidores'!$A$1:$B$65,2,0) -> 20.98 | F21: =VLOOKUP(A21,'Paises Participantes'!$A$1:$B$65,2,0) -> GBR
A22: OKAGBARE Blessing | B22: 11.16 | C22: 11.09 | E22: =VLOOKUP(A22,'Edades de Competidores'!$A$1:$B$65,2,0) -> 27.86 | F22: =VLOOKUP(A22,'Paises Participantes'!$A$1:$B$65,2,0) -> NGR
A23: AHOURE Murielle | B23: 11.17 | C23: 11.01 | E23: =VLOOKUP(A23,'Edades de Competidores'!$A$1:$B$65,2,0) -> 28.99 | F23: =VLOOKUP(A23,'Paises Participantes'!$A$1:$B$65,2,0) -> CIV | I23: Etiquetas de fila | J23: Cuenta de Ronda 3
A24: BARTOLETTA Tianna | B24: 11.23 | C24: 11 | E24: =VLOOKUP(A24,'Edades de Competidores'!$A$1:$B$65,2,0) -> 30.98 | F24: =VLOOKUP(A24,'Paises Participantes'!$A$1:$B$65,2,0) -> USA | I24: JAM | J24: 3
A25: HARRIGAN-SCOTT Tahesia | B25: 11.54 | E25: =VLOOKUP(A25,'Edades de Competidores'!$A$1:$B$65,2,0) -> 34.52 | F25: =VLOOKUP(A25,'Paises Participantes'!$A$1:$B$65,2,0) -> IVB | I25: USA | J25: 2
A26: BAZOLO Lorene Dorcas | B26: 11.43 | E26: =VLOOKUP(A26,'Edades de Competidores'!$A$1:$B$65,2,0) -> 33.3 | F26: =VLOOKUP(A26,'Paises Participantes'!$A$1:$B$65,2,0) -> POR | I26: TTO | J26: 1
A27: LALOVA-COLLIO Ivet | B27: 11.35 | E27: =VLOOKUP(A27,'Edades de Competidores'!$A$1:$B$65,2,0) -> 32.26 | F27: =VLOOKUP(A27,'Paises Participantes'!$A$1:$B$65,2,0) -> BUL | I27: CIV | J27: 1
A28: ASUMNU Gloria | B28: 11.55 | E28: =VLOOKUP(A28,'Edades de Competidores'!$A$1:$B$65,2,0) -> 31.25 | F28: =VLOOKUP(A28,'Paises Participantes'!$A$1:$B$65,2,0) -> NGR | I28: NED | J28: 1
A29: BAPTISTE Kelly-Ann | B29: 11.42 | E29: =VLOOKUP(A29,'Edades de Competidores'!$A$1:$B$65,2,0) -> 29.85 | F29: =VLOOKUP(A29,'Paises Participantes'!$A$1:$B$65,2,0) -> TTO | I29: Total general | J29: 8
A30: ZANG MILAMA Ruddy | B30: 11.67 | E30: =VLOOKUP(A30,'Edades de Competidores'!$A$1:$B$65,2,0) -> 29.21 | F30: =VLOOKUP(A30,'Paises Participantes'!$A$1:$B$65,2,0) -> GAB
A31: PALACIOS Eliecith | B31: 11.48 | E31: =VLOOKUP(A31,'Edades de Competidores'!$A$1:$B$65,2,0) -> 28.93 | F31: =VLOOKUP(A31,'Paises Participantes'!$A$1:$B$65,2,0) -> COL
A32: WISIL Toea | B32: 11.48 | E32: =VLOOKUP(A32,'Edades de Competidores'!$A$1:$B$65,2,0) -> 28.64 | F32: =VLOOKUP(A32,'Paises Participantes'!$A$1:$B$65,2,0) -> PNG | I32: Etiquetas de fila | J32: Cuenta de Edad
A33: STUY Khrystyna | B33: 11.57 | E33: =VLOOKUP(A33,'Edades de Competidores'!$A$1:$B$65,2,0) -> 28.55 | F33: =VLOOKUP(A33,'Paises Participantes'!$A$1:$B$65,2,0) -> UKR | I33: AUS | J33: 1
A34: OKPARAEBO Ezinne | B34: 11.43 | E34: =VLOOKUP(A34,'Edades de Competidores'!$A$1:$B$65,2,0) -> 28.47 | F34: =VLOOKUP(A34,'Paises Participantes'!$A$1:$B$65,2,0) -> NOR | I34: BAH | J34: 1
A35: KRASUCKI Franciela | B35: 11.67 | E35: =VLOOKUP(A35,'Edades de Competidores'!$A$1:$B$65,2,0) -> 28.32 | F35: =VLOOKUP(A35,'Paises Participantes'!$A$1:$B$65,2,0) -> BRA | I35: BRA | J35: 2
A36: POPOWICZ-DRAPALA Marika | B36: 11.7 | E36: =VLOOKUP(A36,'Edades de Competidores'!$A$1:$B$65,2,0) -> 28.31 | F36: =VLOOKUP(A36,'Paises Participantes'!$A$1:$B$65,2,0) -> POL | I36: BRN | J36: 2
A37: OWUSU-AGYAPONG Flings | B37: 11.43 | E37: =VLOOKUP(A37,'Edades de Competidores'!$A$1:$B$65,2,0) -> 27.84 | F37: =VLOOKUP(A37,'Paises Participantes'!$A$1:$B$65,2,0) -> GHA | I37: BUL | J37: 1
A38: PAPAIOANNOU Ramona | B38: 11.61 | E38: =VLOOKUP(A38,'Edades de Competidores'!$A$1:$B$65,2,0) -> 27.18 | F38: =VLOOKUP(A38,'Paises Participantes'!$A$1:$B$65,2,0) -> CYP | I38: CAN | J38: 2
A39: WAHI Sunayna | B39: 12.25 | E39: =VLOOKUP(A39,'Edades de Competidores'!$A$1:$B$65,2,0) -> 26.02 | F39: =VLOOKUP(A39,'Paises Participantes'!$A$1:$B$65,2,0) -> SUR | I39: CGO | J39: 1
A40: BREEN Melissa | B40: 11.74 | E40: =VLOOKUP(A40,'Edades de Competidores'!$A$1:$B$65,2,0) -> 25.92 | F40: =VLOOKUP(A40,'Paises Participantes'!$A$1:$B$65,2,0) -> AUS | I40: CHN | J40: 2
...

Sheet Paises Participantes
A1: Nombre | B1: Pais
A2: WILLIAMS Christania | B2: JAM
A3: THOMPSON Elaine | B3: JAM
A4: SCHIPPERS Dafne | B4: NED
A5: HENRY Desiree | B5: GBR
A6: GARDNER English | B6: USA
A7: AHYE Michelle-Lee | B7: TTO
A8: OKAGBARE Blessing | B8: NGR
A9: BOWIE Tori | B9: USA
A10: AHOURE Murielle | B10: CIV
A11: KAMBUNDJI Mujinga | B11: SUI
A12: TA LOU Marie-Josee | B12: CIV
... A65: RIVERA Evelyn | B65: COL

Sheet Edades de Competidores
A1: Nombre | B1: Edad
A2: RIVERA Evelyn | B2: 18.71
A3: AL-ALAWI Mazoon | B3: 18.76
A4: SWOBODA Ewa | B4: 19.06
A5: JASIM Iman Essa | B5: 19.11
A6: NEITA Daryll | B6: 19.97
A7: THOMPSON Brenessa | B7: 20.07
A8: CHAND Dutee | B8: 20.54
A9: TENORIO Angela | B9: 20.56
A10: SEAVULA Sisila | B10: 20.76
A11: YUAN Qiqi | B11: 20.81
A12: HENRY Desiree | B12: 20.98
A13: SHARIPOVA Nigina | B13: 21.02
... A65: HARRIGAN-SCOTT Tahesia | B65: 34.52

Sheet Preguntas
A1: Question 1 | B1: Cantidad de Competidores | G1: País | H1: AHOURE Murielle
A2: ¿Cuántos competidores menores de 25 años hubo en la ronda 2? | B2: 10 | D2: =IF(B2="","",IF(B2=10,"✔","✘")) -> ✔ | G2: JAM | H2: AHYE Michelle-Lee
G3: NED | H3: AL-ALAWI Mazoon
A4: Question 2 | B4: País (Iniciales) | G4: GBR | H4: ALKHALDI Hajar
A5: ¿Cuál pais ha traido la mayor cantidad de personas a la ronda 3? | B5: JAM | D5: =IF(B5="","",IF(B5="JAM","✔","✘")) -> ✔ | G5: USA | H5: ASUMNU Gloria
G6: TTO | H6: BAPTISTE Kelly-Ann
A7: Question 3 | B7: Competidor | G7: NGR | H7: BARTOLETTA Tianna
A8: ¿Quién es el competidor de menor edad, participando en las 3 rondas? | B8: WILLIAMS Christania | D8: =IF(B8="","",IF(B8="WILLIAMS Christania","✔","✘")) -> ✔ | G8: CIV | H8: BAZOLO Lorene Dorcas
G9: SUI | H9: BINGHAM Khamica
A10: Question 4 | B10: Competidor | G10: POL | H10: BOUELE Cecilia
A11: ¿Quién es el competidor de mayor edad en no pasar de la ronda 1? | B11: HARRIGAN-SCOTT Tahesia | D11: =IF(B11="","",IF(B11="HARRIGAN-SCOTT Tahesia","✔","✘")) -> ✔ | G11: BRA | H11: BOWIE Tori
G12: UKR | H12: BREEN Melissa
A13: Question 5 | B13: Diferencia de edades (pon sólo 2 decimales) | G13: GER | H13: CHAND Dutee
A14: ¿Cuáles es la diferencia de edad entre el competidor más joven y el mas viejo de Jamaica? | B14: 7.81 | D14: =IF(B14="","",IF(B14=7.81,"✔","✘")) -> ✔ | G14: RSA | H14: CONLEY Alyssa
G15: IVB | H15: EMMANUEL Crystal
A16: Question 6 | B16: Tiempo promedio (pon sólo 2 decimales) | G16: ECU | H16: FRASER-PRYCE Shelly-Ann
A17: ¿Cuál es el tiempo promedio de los competidores de USA (todas las rondas)? | B17: 11 | D17: =IF(B17="","",IF(B17=11,"✔","✘")) -> ✔ | G17: POR | H17: GAITHER Tynia
G18: BUL | H18: GARDNER English
G19: GAB | H19: HAASE Rebekka
G20: COL | H20: HACKETT Semoy
G21: PNG | H21: HARRIGAN-SCOTT Tahesia
G22: NOR | H22: HENRY Desiree
G23: GHA | H23: HORN Carina
G24: CYP | H24: JASIM Iman Essa
G25: SUR | H25: KAMARA Hafsatu
G26: AUS | H26: KAMBUNDJI Mujinga
G27: CHN | H27: KASHAFUTDINOVA Rima
G28: KAZ | H28: KRASUCKI Franciela
G29: CAN | H29: LALOVA-COLLIO Ivet
... G41: OMA | H41: POPOWICZ-DRAPALA Marika
H42: POVKH Olesya
H43: RIVERA Evelyn
H44: SAFRONOVA Olga
H45: SANTOS Rosangela
H46: SCHIPPERS Dafne
H47: SEAVULA Sisila
H48: SHARIPOVA Nigina
H49: STUY Khrystyna
H50: SWOBODA Ewa
H51: TA LOU Marie-Josee
...
